Workbook

Sheet Сводная табл
A1: 1.1. Данные в разрезе недель и Территорий. | E1: Топ-3 по доле в общем товарообороте | H1: Топ-3 территорий по товарообороту на склад за последнюю неделю
H2: Неделя | I2: 23
A3: Территория/Неделя | B3: Сумма по полю Товарооборот, руб | C3: Сумма по полю Товарооборот на склад | E3: Территория/Неделя | F3: Сумма по полю Товарооборот, руб
A4: Волгоград | B4: 218000127 | C4: 6029485.6 | E4: Санкт-Петербург Север | F4: 0.27823941 | H4: Территория/Неделя | I4: Сумма по полю Товарооборот на склад
A5: 18 | B5: 36934095 | C5: 1025947.1 | E5: Санкт-Петербург Юг | F5: 0.20869355 | H5: Москва Восток | I5: 350262.86
A6: 19 | B6: 43307156 | C6: 1202976.5 | E6: Москва Запад | F6: 0.15600381 | H6: Москва Запад | I6: 329921.57
A7: 20 | B7: 41300679 | C7: 1147241.1 | E7: Москва Восток | F7: 0.14874466 | H7: Санкт-Петербург Север | I7: 302909.27
A8: 21 | B8: 44172813 | C8: 1227022.6 | E8: Екатеринбург | F8: 0.049051065 | H8: Екатеринбург | I8: 220320.05
A9: 22 | B9: 46485094 | C9: 1269533.7 | E9: Волгоград | F9: 0.043930743 | H9: Санкт-Петербург Юг | I9: 216953.85
A10: 23 | B10: 5800290 | C10: 156764.59 | E10: Казань | F10: 0.024299498 | H10: Казань | I10: 168054.39
A11: Екатеринбург | B11: 2.43409e+08 | C11: 7851903.3 | E11: Кемерово | F11: 0.020488951 | H11: Волгоград | I11: 156764.59
A12: 18 | B12: 42828758 | C12: 1381572.8 | E12: Нижний Новгород | F12: 0.019263478 | H12: Нижний Новгород | I12: 150675.6
A13: 19 | B13: 46366010 | C13: 1495677.7 | E13: Краснодар | F13: 0.017302774 | H13: Кемерово | I13: 140239.79
A14: 20 | B14: 47079842 | C14: 1518704.6 | E14: Пермь | F14: 0.0098346447 | H14: Краснодар | I14: 120903.21
A15: 21 | B15: 49575288 | C15: 1599202.8 | E15: Новосибирск | F15: 0.0082691777 | H15: Тюмень | I15: 114635.36
A16: 22 | B16: 50729186 | C16: 1636425.3 | E16: Ростов-на-Дону | F16: 0.0070161281 | H16: Тольятти | I16: 100774.2
A17: 23 | B17: 6829921.5 | C17: 220320.05 | E17: Тольятти | F17: 0.0066918904 | H17: Ростов-на-Дону | I17: 97852.031
A18: Казань | B18: 120582837 | C18: 5758962.4 | E18: Тюмень | F18: 0.001141424 | H18: Пермь | I18: 89800.5
A19: 18 | B19: 17828216 | C19: 905861.29 | E19: Самара | F19: 0.0006735906 | H19: Новосибирск | I19: 71845.5
A20: 19 | B20: 20974521 | C20: 1018321.6 | E20: Томск | F20: 0.00017792061 | H20: Уфа | I20: 68482
A21: 20 | B21: 23603355 | C21: 1123969.3 | E21: Уфа | F21: 0.00017728009 | H21: Томск | I21: 43223.667
A22: 21 | B22: 26815804 | C22: 1276943.1 | E22: Общий итог | F22: 1 | H22: Самара | I22: 42423
A23: 22 | B23: 27495690 | C23: 1265812.7 | H23: Общий итог | I23: 2786041.4
A24: 23 | B24: 3865251 | C24: 168054.39
A25: Кемерово | B25: 1.0167354e+08 | C25: 5019070.5
A26: 18 | B26: 16029680 | C26: 868773.03
A27: 19 | B27: 19479056 | C27: 947140.01
A28: 20 | B28: 19724733 | C28: 939273
A29: 21 | B29: 20915751 | C29: 1002951.8
A30: 22 | B30: 22579281 | C30: 1120692.9
A31: 23 | B31: 2945035.5 | C31: 140239.79
A32: Краснодар | B32: 85862582 | C32: 4464328.5
A33: 18 | B33: 13955985 | C33: 748086.89
A34: 19 | B34: 16391856 | C34: 862729.26
A35: 20 | B35: 16732521 | C35: 880659
A36: 21 | B36: 17647479 | C36: 928814.68
A37: 22 | B37: 18595773 | C37: 923135.5
A38: 23 | B38: 2538967.5 | C38: 120903.21
A39: Москва Восток | B39: 738124428 | C39: 13668971
A40: 18 | B40: 130713645 | C40: 2420623.1
...

Sheet Диаграмма
A3: Названия строк | B3: Сумма по полю Товарооборот, руб | C3: Сумма по полю Товарооборот на склад
A4: 18 | B4: 836803032 | C4: 15050189
A5: 19 | B5: 9.8391541e+08 | C5: 17810867
A6: 20 | B6: 9.4726301e+08 | C6: 17504431
A7: 21 | B7: 1.0026919e+09 | C7: 18752595
A8: 22 | B8: 1.0556535e+09 | C8: 20458987
A9: 23 | B9: 1.3603238e+08 | C9: 2786041.4
A10: Общий итог | B10: 4.9623592e+09 | C10: 92363110

Sheet Лист1
A1: Дата | B1: Территория | C1: Товарооборот, шт | D1: Товарооборот, руб | E1: Количество складов | F1: Количество заказов | G1: Количество клиентов | H1: Товарооборот на склад | I1: Неделя
A2: 43982 | B2: Самара | C2: 7944 | D2: 623971.5 | E2: =SUMIFS(Лист2!$C:$C,Лист2!$B:$B,Лист1!$B2,Лист2!$A:$A,Лист1!$A2) -> 15 | F2: =SUMIFS(Лист2!$D:$D,Лист2!$B:$B,Лист1!$B2,Лист2!$A:$A,Лист1!$A2) -> 441 | G2: =SUMIFS(Лист2!$E:$E,Лист2!$B:$B,Лист1!$B2,Лист2!$A:$A,Лист1!$A2) -> 368 | H2: =D2/E2 -> 41598.1 | I2: =WEEKNUM(A2,2) -> 22
A3: 43981 | B3: Самара | C3: 10029 | D3: 787101 | E3: =SUMIFS(Лист2!C:C,Лист2!B:B,Лист1!B3,Лист2!A:A,Лист1!A3) -> 15 | F3: =SUMIFS(Лист2!$D:$D,Лист2!$B:$B,Лист1!$B3,Лист2!$A:$A,Лист1!$A3) -> 490 | G3: =SUMIFS(Лист2!$E:$E,Лист2!$B:$B,Лист1!$B3,Лист2!$A:$A,Лист1!$A3) -> 409 | H3: =D3/E3 -> 52473.4 | I3: =WEEKNUM(A3,2) -> 22
A4: 43979 | B4: Самара | C4: 8536.5 | D4: 643944 | E4: =SUMIFS(Лист2!C:C,Лист2!B:B,Лист1!B4,Лист2!A:A,Лист1!A4) -> 15 | F4: =SUMIFS(Лист2!$D:$D,Лист2!$B:$B,Лист1!$B4,Лист2!$A:$A,Лист1!$A4) -> 464 | G4: =SUMIFS(Лист2!$E:$E,Лист2!$B:$B,Лист1!$B4,Лист2!$A:$A,Лист1!$A4) -> 390 | H4: =D4/E4 -> 42929.6 | I4: =WEEKNUM(A4,2) -> 22
A5: 43967 | B5: Кемерово | C5: 38947.5 | D5: 3395892 | E5: =SUMIFS(Лист2!C:C,Лист2!B:B,Лист1!B5,Лист2!A:A,Лист1!A5) -> 21 | F5: =SUMIFS(Лист2!$D:$D,Лист2!$B:$B,Лист1!$B5,Лист2!$A:$A,Лист1!$A5) -> 2145 | G5: =SUMIFS(Лист2!$E:$E,Лист2!$B:$B,Лист1!$B5,Лист2!$A:$A,Лист1!$A5) -> 1947 | H5: =D5/E5 -> 161709.14 | I5: =WEEKNUM(A5,2) -> 20
A6: 43970 | B6: Кемерово | C6: 31842 | D6: 2771116.5 | E6: =SUMIFS(Лист2!C:C,Лист2!B:B,Лист1!B6,Лист2!A:A,Лист1!A6) -> 21 | F6: =SUMIFS(Лист2!$D:$D,Лист2!$B:$B,Лист1!$B6,Лист2!$A:$A,Лист1!$A6) -> 1860 | G6: =SUMIFS(Лист2!$E:$E,Лист2!$B:$B,Лист1!$B6,Лист2!$A:$A,Лист1!$A6) -> 1704 | H6: =D6/E6 -> 131957.93 | I6: =WEEKNUM(A6,2) -> 21
A7: 43968 | B7: Кемерово | C7: 32023.5 | D7: 2882458.5 | E7: =SUMIFS(Лист2!C:C,Лист2!B:B,Лист1!B7,Лист2!A:A,Лист1!A7) -> 21 | F7: =SUMIFS(Лист2!$D:$D,Лист2!$B:$B,Лист1!$B7,Лист2!$A:$A,Лист1!$A7) -> 1874 | G7: =SUMIFS(Лист2!$E:$E,Лист2!$B:$B,Лист1!$B7,Лист2!$A:$A,Лист1!$A7) -> 1705 | H7: =D7/E7 -> 137259.93 | I7: =WEEKNUM(A7,2) -> 20
A8: 43960 | B8: Кемерово | C8: 31147.5 | D8: 2831019 | E8: =SUMIFS(Лист2!C:C,Лист2!B:B,Лист1!B8,Лист2!A:A,Лист1!A8) -> 21 | F8: =SUMIFS(Лист2!$D:$D,Лист2!$B:$B,Лист1!$B8,Лист2!$A:$A,Лист1!$A8) -> 1735 | G8: =SUMIFS(Лист2!$E:$E,Лист2!$B:$B,Лист1!$B8,Лист2!$A:$A,Лист1!$A8) -> 1568 | H8: =D8/E8 -> 134810.43 | I8: =WEEKNUM(A8,2) -> 19
A9: 43955 | B9: Кемерово | C9: 25566 | D9: 2372310 | E9: =SUMIFS(Лист2!C:C,Лист2!B:B,Лист1!B9,Лист2!A:A,Лист1!A9) -> 20 | F9: =SUMIFS(Лист2!$D:$D,Лист2!$B:$B,Лист1!$B9,Лист2!$A:$A,Лист1!$A9) -> 1519 | G9: =SUMIFS(Лист2!$E:$E,Лист2!$B:$B,Лист1!$B9,Лист2!$A:$A,Лист1!$A9) -> 1372 | H9: =D9/E9 -> 118615.5 | I9: =WEEKNUM(A9,2) -> 19
A10: 43950 | B10: Кемерово | C10: 29319 | D10: 2623480.5 | E10: =SUMIFS(Лист2!C:C,Лист2!B:B,Лист1!B10,Лист2!A:A,Лист1!A10) -> 18 | F10: =SUMIFS(Лист2!$D:$D,Лист2!$B:$B,Лист1!$B10,Лист2!$A:$A,Лист1!$A10) -> 1684 | G10: =SUMIFS(Лист2!$E:$E,Лист2!$B:$B,Лист1!$B10,Лист2!$A:$A,Лист1!$A10) -> 1528 | H10: =D10/E10 -> 145748.92 | I10: =WEEKNUM(A10,2) -> 18
A11: 43953 | B11: Кемерово | C11: 29031 | D11: 2711247 | E11: =SUMIFS(Лист2!C:C,Лист2!B:B,Лист1!B11,Лист2!A:A,Лист1!A11) -> 18 | F11: =SUMIFS(Лист2!$D:$D,Лист2!$B:$B,Лист1!$B11,Лист2!$A:$A,Лист1!$A11) -> 1708 | G11: =SUMIFS(Лист2!$E:$E,Лист2!$B:$B,Лист1!$B11,Лист2!$A:$A,Лист1!$A11) -> 1534 | H11: =D11/E11 -> 150624.83 | I11: =WEEKNUM(A11,2) -> 18
A12: 43977 | B12: Кемерово | C12: 33423 | D12: 2970330 | E12: =SUMIFS(Лист2!C:C,Лист2!B:B,Лист1!B12,Лист2!A:A,Лист1!A12) -> 20 | F12: =SUMIFS(Лист2!$D:$D,Лист2!$B:$B,Лист1!$B12,Лист2!$A:$A,Лист1!$A12) -> 2044 | G12: =SUMIFS(Лист2!$E:$E,Лист2!$B:$B,Лист1!$B12,Лист2!$A:$A,Лист1!$A12) -> 1863 | H12: =D12/E12 -> 148516.5 | I12: =WEEKNUM(A12,2) -> 22
A13: 43952 | B13: Кемерово | C13: 32487 | D13: 3031254 | E13: =SUMIFS(Лист2!C:C,Лист2!B:B,Лист1!B13,Лист2!A:A,Лист1!A13) -> 18 | F13: =SUMIFS(Лист2!$D:$D,Лист2!$B:$B,Лист1!$B13,Лист2!$A:$A,Лист1!$A13) -> 1826 | G13: =SUMIFS(Лист2!$E:$E,Лист2!$B:$B,Лист1!$B13,Лист2!$A:$A,Лист1!$A13) -> 1633 | H13: =D13/E13 -> 168403 | I13: =WEEKNUM(A13,2) -> 18
A14: 43963 | B14: Кемерово | C14: 28219.5 | D14: 2595778.5 | E14: =SUMIFS(Лист2!C:C,Лист2!B:B,Лист1!B14,Лист2!A:A,Лист1!A14) -> 21 | F14: =SUMIFS(Лист2!$D:$D,Лист2!$B:$B,Лист1!$B14,Лист2!$A:$A,Лист1!$A14) -> 1656 | G14: =SUMIFS(Лист2!$E:$E,Лист2!$B:$B,Лист1!$B14,Лист2!$A:$A,Лист1!$A14) -> 1516 | H14: =D14/E14 -> 123608.5 | I14: =WEEKNUM(A14,2) -> 20
... A505: 43983 | B505: Новосибирск | C505: 14238 | D505: 1293219 | E505: =SUMIFS(Лист2!C:C,Лист2!B:B,Лист1!B505,Лист2!A:A,Лист1!A505) -> 18 | F505: =SUMIFS(Лист2!$D:$D,Лист2!$B:$B,Лист1!$B505,Лист2!$A:$A,Лист1!$A505) -> 923 | G505: =SUMIFS(Лист2!$E:$E,Лист2!$B:$B,Лист1!$B505,Лист2!$A:$A,Лист1!$A505) -> 824 | H505: =D505/E505 -> 71845.5 | I505: =WEEKNUM(A505,2) -> 23

Sheet Лист2
A1: Дата | B1: Территория | C1: Количество складов | D1: Количество заказов | E1: Количество клиентов
A2: 43949 | B2: Волгоград | C2: 36 | D2: 4923 | E2: 4560
A3: 43949 | B3: Екатеринбург | C3: 31 | D3: 5465 | E3: 5096
A4: 43949 | B4: Казань | C4: 19 | D4: 1846 | E4: 1681
A5: 43949 | B5: Кемерово | C5: 18 | D5: 1539 | E5: 1404
A6: 43949 | B6: Краснодар | C6: 18 | D6: 1505 | E6: 1368
A7: 43949 | B7: Москва Восток | C7: 54 | D7: 12306 | E7: 11532
A8: 43949 | B8: Москва Запад | C8: 59 | D8: 12943 | E8: 12072
A9: 43949 | B9: Нижний Новгород | C9: 17 | D9: 1439 | E9: 1265
A10: 43949 | B10: Новосибирск | C10: 15 | D10: 636 | E10: 547
A11: 43949 | B11: Пермь | C11: 15 | D11: 780 | E11: 690
A12: 43949 | B12: Санкт-Петербург Север | C12: 125 | D12: 20914 | E12: 19479
A13: 43949 | B13: Санкт-Петербург Юг | C13: 128 | D13: 16450 | E13: 15320
... A505: 43983 | B505: Уфа | C505: 6 | D505: 237 | E505: 175
